Workbook
Name 次要关键词: OFFSET(首次要关键词!$A$1,MATCH(网址列表!$J1,首次要关键词!$A$2:$A$33,0),3,1,OFFSET(首次要关键词!$A$1,MATCH(网址列表!$J1,首次要关键词!$A$2:$A$33,0),2,1,1))
Name 次要关键词数量: 表_首次要关键词[次要关键词数量]
Name 首要关键词: OFFSET(首次要关键词!$A$1,1,0,COUNTIF(表_首次要关键词[首要关键词],"<>"),1)
Name 首要关键词排序: 表_首次要关键词[排序]
Name 重点关键词: OFFSET(重点关键词!$A$1,MATCH(网址列表!$J2,首要关键词,0)*50-48,MATCH(网址列表!$K2,次要关键词,0),重点关键词数量,1)
Name 重点关键词数量: OFFSET(重点关键词!$A$1,MATCH(网址列表!$J1,首要关键词,0)*50-49,MATCH(网址列表!$K1,次要关键词,0),1,1)

Sheet 网址列表
A1: 序号 | B1: 1级 | C1: 2级 | D1: 3级 | E1: 级内 | F1: 简称 | G1: 网址 | H1: 描述title | I1: 图标地址 | J1: 首要关键词 | K1: 次要关键词 | L1: 重点关键词 | M1: 判断网址 | N1: 判断图片 | O1: 其他标签 | P1: 图标大小 | Q1: 备案/未备案 | R1: 经营性/非经营性
A2: =表_网址[[#This Row],[1级]]&"-"&表_网址[[#This Row],[2级]]&"-"&表_网址[[#This Row],[3级]]&"-"&表_网址[[#This Row],[级内]] -> 101-10-10-101 | B2: =VLOOKUP(表_网址[[#This Row],[首要关键词]],表_首次要关键词[[首要关键词]:[排序]],2,0) -> 101 | C2: =IF(表_网址[[#This Row],[次要关键词]]="",10,MATCH(表_网址[[#This Row],[次要关键词]],次要关键词,0)+10) -> 10 | D2: =IF(表_网址[[#This Row],[重点关键词]]="",10,MATCH(表_网址[[#This Row],[重点关键词]],OFFSET(重点关键词!$A$1,MATCH($J2,首要关键词,0)*50-48,MATCH($K2,次要关键词,0),重点关键词数量,1),0)+10) -> 10 | E2: =IF(AND(表_网址[[#This Row],[1级]]=B1,表_网址[[#This Row],[2级]]=C1,表_网址[[#This Row],[3级]]=D1),E1+1,101) -> 101 | F2: 中国政府网 | G2: http://www.gov.cn/ | H2: 中华人民共和国中央人民政府 | I2: http://www.gov.cn/govweb/xhtml/favicon.ico | J2: 政府 | M2: 999 | N2: 999 | P2: 16
A3: =表_网址[[#This Row],[1级]]&"-"&表_网址[[#This Row],[2级]]&"-"&表_网址[[#This Row],[3级]]&"-"&表_网址[[#This Row],[级内]] -> 101-11-10-101 | B3: =VLOOKUP(表_网址[[#This Row],[首要关键词]],表_首次要关键词[[首要关键词]:[排序]],2,0) -> 101 | C3: =IF(表_网址[[#This Row],[次要关键词]]="",10,MATCH(表_网址[[#This Row],[次要关键词]],次要关键词,0)+10) -> 11 | D3: =IF(表_网址[[#This Row],[重点关键词]]="",10,MATCH(表_网址[[#This Row],[重点关键词]],OFFSET(重点关键词!$A$1,MATCH($J3,首要关键词,0)*50-48,MATCH($K3,次要关键词,0),重点关键词数量,1),0)+10) -> 10 | E3: =IF(AND(表_网址[[#This Row],[1级]]=B2,表_网址[[#This Row],[2级]]=C2,表_网址[[#This Row],[3级]]=D2),E2+1,101) -> 101 | F3: 国务院办公厅 | J3: 政府 | K3: 国务院
A4: =表_网址[[#This Row],[1级]]&"-"&表_网址[[#This Row],[2级]]&"-"&表_网址[[#This Row],[3级]]&"-"&表_网址[[#This Row],[级内]] -> 101-11-11-101 | B4: =VLOOKUP(表_网址[[#This Row],[首要关键词]],表_首次要关键词[[首要关键词]:[排序]],2,0) -> 101 | C4: =IF(表_网址[[#This Row],[次要关键词]]="",10,MATCH(表_网址[[#This Row],[次要关键词]],次要关键词,0)+10) -> 11 | D4: =IF(表_网址[[#This Row],[重点关键词]]="",10,MATCH(表_网址[[#This Row],[重点关键词]],OFFSET(重点关键词!$A$1,MATCH($J4,首要关键词,0)*50-48,MATCH($K4,次要关键词,0),重点关键词数量,1),0)+10) -> 11 | E4: =IF(AND(表_网址[[#This Row],[1级]]=B3,表_网址[[#This Row],[2级]]=C3,表_网址[[#This Row],[3级]]=D3),E3+1,101) -> 101 | F4: 外交部 | G4: https://www.fmprc.gov.cn/web/ | I4: https://www.google.com/s2/favicons?domain=https://www.fmprc.gov.cn/web/ | J4: 政府 | K4: 国务院 | L4: 组成部门 | M4: 999
A5: =表_网址[[#This Row],[1级]]&"-"&表_网址[[#This Row],[2级]]&"-"&表_网址[[#This Row],[3级]]&"-"&表_网址[[#This Row],[级内]] -> 101-11-11-102 | B5: =VLOOKUP(表_网址[[#This Row],[首要关键词]],表_首次要关键词[[首要关键词]:[排序]],2,0) -> 101 | C5: =IF(表_网址[[#This Row],[次要关键词]]="",10,MATCH(表_网址[[#This Row],[次要关键词]],次要关键词,0)+10) -> 11 | D5: =IF(表_网址[[#This Row],[重点关键词]]="",10,MATCH(表_网址[[#This Row],[重点关键词]],OFFSET(重点关键词!$A$1,MATCH($J5,首要关键词,0)*50-48,MATCH($K5,次要关键词,0),重点关键词数量,1),0)+10) -> 11 | E5: =IF(AND(表_网址[[#This Row],[1级]]=B4,表_网址[[#This Row],[2级]]=C4,表_网址[[#This Row],[3级]]=D4),E4+1,101) -> 102 | F5: 国防部 | G5: http://www.mod.gov.cn/ | I5: http://www.mod.gov.cn/favicon.ico | J5: 政府 | K5: 国务院 | L5: 组成部门 | M5: 999 | P5: 256
A6: =表_网址[[#This Row],[1级]]&"-"&表_网址[[#This Row],[2级]]&"-"&表_网址[[#This Row],[3级]]&"-"&表_网址[[#This Row],[级内]] -> 101-11-11-103 | B6: =VLOOKUP(表_网址[[#This Row],[首要关键词]],表_首次要关键词[[首要关键词]:[排序]],2,0) -> 101 | C6: =IF(表_网址[[#This Row],[次要关键词]]="",10,MATCH(表_网址[[#This Row],[次要关键词]],次要关键词,0)+10) -> 11 | D6: =IF(表_网址[[#This Row],[重点关键词]]="",10,MATCH(表_网址[[#This Row],[重点关键词]],OFFSET(重点关键词!$A$1,MATCH($J6,首要关键词,0)*50-48,MATCH($K6,次要关键词,0),重点关键词数量,1),0)+10) -> 11 | E6: =IF(AND(表_网址[[#This Row],[1级]]=B5,表_网址[[#This Row],[2级]]=C5,表_网址[[#This Row],[3级]]=D5),E5+1,101) -> 103 | F6: 国家发展和改革委员会 | G6: https://www.ndrc.gov.cn/ | I6: https://www.google.com/s2/favicons?domain=https://www.ndrc.gov.cn/ | J6: 政府 | K6: 国务院 | L6: 组成部门 | M6: 999
A7: =表_网址[[#This Row],[1级]]&"-"&表_网址[[#This Row],[2级]]&"-"&表_网址[[#This Row],[3级]]&"-"&表_网址[[#This Row],[级内]] -> 101-11-11-104 | B7: =VLOOKUP(表_网址[[#This Row],[首要关键词]],表_首次要关键词[[首要关键词]:[排序]],2,0) -> 101 | C7: =IF(表_网址[[#This Row],[次要关键词]]="",10,MATCH(表_网址[[#This Row],[次要关键词]],次要关键词,0)+10) -> 11 | D7: =IF(表_网址[[#This Row],[重点关键词]]="",10,MATCH(表_网址[[#This Row],[重点关键词]],OFFSET(重点关键词!$A$1,MATCH($J7,首要关键词,0)*50-48,MATCH($K7,次要关键词,0),重点关键词数量,1),0)+10) -> 11 | E7: =IF(AND(表_网址[[#This Row],[1级]]=B6,表_网址[[#This Row],[2级]]=C6,表_网址[[#This Row],[3级]]=D6),E6+1,101) -> 104 | F7: 教育部 | G7: http://www.moe.gov.cn/ | I7: http://www.moe.gov.cn/favorite.ico | J7: 政府 | K7: 国务院 | L7: 组成部门 | M7: 999 | P7: 16
A8: =表_网址[[#This Row],[1级]]&"-"&表_网址[[#This Row],[2级]]&"-"&表_网址[[#This Row],[3级]]&"-"&表_网址[[#This Row],[级内]] -> 101-11-11-105 | B8: =VLOOKUP(表_网址[[#This Row],[首要关键词]],表_首次要关键词[[首要关键词]:[排序]],2,0) -> 101 | C8: =IF(表_网址[[#This Row],[次要关键词]]="",10,MATCH(表_网址[[#This Row],[次要关键词]],次要关键词,0)+10) -> 11 | D8: =IF(表_网址[[#This Row],[重点关键词]]="",10,MATCH(表_网址[[#This Row],[重点关键词]],OFFSET(重点关键词!$A$1,MATCH($J8,首要关键词,0)*50-48,MATCH($K8,次要关键词,0),重点关键词数量,1),0)+10) -> 11 | E8: =IF(AND(表_网址[[#This Row],[1级]]=B7,表_网址[[#This Row],[2级]]=C7,表_网址[[#This Row],[3级]]=D7),E7+1,101) -> 105 | F8: (国家语言文字工作委员会) | G8: http://www.moe.gov.cn/jyb_sy/China_Language/ | I8: http://www.moe.gov.cn/favorite.ico | J8: 政府 | K8: 国务院 | L8: 组成部门 | M8: 999 | P8: 16
A9: =表_网址[[#This Row],[1级]]&"-"&表_网址[[#This Row],[2级]]&"-"&表_网址[[#This Row],[3级]]&"-"&表_网址[[#This Row],[级内]] -> 101-11-11-106 | B9: =VLOOKUP(表_网址[[#This Row],[首要关键词]],表_首次要关键词[[首要关键词]:[排序]],2,0) -> 101 | C9: =IF(表_网址[[#This Row],[次要关键词]]="",10,MATCH(表_网址[[#This Row],[次要关键词]],次要关键词,0)+10) -> 11 | D9: =IF(表_网址[[#This Row],[重点关键词]]="",10,MATCH(表_网址[[#This Row],[重点关键词]],OFFSET(重点关键词!$A$1,MATCH($J9,首要关键词,0)*50-48,MATCH($K9,次要关键词,0),重点关键词数量,1),0)+10) -> 11 | E9: =IF(AND(表_网址[[#This Row],[1级]]=B8,表_网址[[#This Row],[2级]]=C8,表_网址[[#This Row],[3级]]=D8),E8+1,101) -> 106 | F9: 科学技术部 | G9: http://www.most.gov.cn/ | I9: http://www.most.gov.cn/favicon.ico | J9: 政府 | K9: 国务院 | L9: 组成部门 | M9: 999 | P9: 16
A10: =表_网址[[#This Row],[1级]]&"-"&表_网址[[#This Row],[2级]]&"-"&表_网址[[#This Row],[3级]]&"-"&表_网址[[#This Row],[级内]] -> 101-11-11-107 | B10: =VLOOKUP(表_网址[[#This Row],[首要关键词]],表_首次要关键词[[首要关键词]:[排序]],2,0) -> 101 | C10: =IF(表_网址[[#This Row],[次要关键词]]="",10,MATCH(表_网址[[#This Row],[次要关键词]],次要关键词,0)+10) -> 11 | D10: =IF(表_网址[[#This Row],[重点关键词]]="",10,MATCH(表_网址[[#This Row],[重点关键词]],OFFSET(重点关键词!$A$1,MATCH($J10,首要关键词,0)*50-48,MATCH($K10,次要关键词,0),重点关键词数量,1),0)+10) -> 11 | E10: =IF(AND(表_网址[[#This Row],[1级]]=B9,表_网址[[#This Row],[2级]]=C9,表_网址[[#This Row],[3级]]=D9),E9+1,101) -> 107 | F10: 工业和信息化部 | G10: https://www.miit.gov.cn/ | I10: https://www.miit.gov.cn/favicon.ico | J10: 政府 | K10: 国务院 | L10: 组成部门 | M10: 999 | N10: 999 | P10: 32
A11: =表_网址[[#This Row],[1级]]&"-"&表_网址[[#This Row],[2级]]&"-"&表_网址[[#This Row],[3级]]&"-"&表_网址[[#This Row],[级内]] -> 101-11-11-108 | B11: =VLOOKUP(表_网址[[#This Row],[首要关键词]],表_首次要关键词[[首要关键词]:[排序]],2,0) -> 101 | C11: =IF(表_网址[[#This Row],[次要关键词]]="",10,MATCH(表_网址[[#This Row],[次要关键词]],次要关键词,0)+10) -> 11 | D11: =IF(表_网址[[#This Row],[重点关键词]]="",10,MATCH(表_网址[[#This Row],[重点关键词]],OFFSET(重点关键词!$A$1,MATCH($J11,首要关键词,0)*50-48,MATCH($K11,次要关键词,0),重点关键词数量,1),0)+10) -> 11 | E11: =IF(AND(表_网址[[#This Row],[1级]]=B10,表_网址[[#This Row],[2级]]=C10,表_网址[[#This Row],[3级]]=D10),E10+1,101) -> 108 | F11: (国家航天局) | G11: http://www.cnsa.gov.cn/ | I11: https://www.google.com/s2/favicons?domain=http://www.cnsa.gov.cn/ | J11: 政府 | K11: 国务院 | L11: 组成部门 | M11: 999
A12: =表_网址[[#This Row],[1级]]&"-"&表_网址[[#This Row],[2级]]&"-"&表_网址[[#This Row],[3级]]&"-"&表_网址[[#This Row],[级内]] -> 101-11-11-109 | B12: =VLOOKUP(表_网址[[#This Row],[首要关键词]],表_首次要关键词[[首要关键词]:[排序]],2,0) -> 101 | C12: =IF(表_网址[[#This Row],[次要关键词]]="",10,MATCH(表_网址[[#This Row],[次要关键词]],次要关键词,0)+10) -> 11 | D12: =IF(表_网址[[#This Row],[重点关键词]]="",10,MATCH(表_网址[[#This Row],[重点关键词]],OFFSET(重点关键词!$A$1,MATCH($J12,首要关键词,0)*50-48,MATCH($K12,次要关键词,0),重点关键词数量,1),0)+10) -> 11 | E12: =IF(AND(表_网址[[#This Row],[1级]]=B11,表_网址[[#This Row],[2级]]=C11,表_网址[[#This Row],[3级]]=D11),E11+1,101) -> 109 | F12: (国家原子能机构) | G12: http://www.caea.gov.cn/ | I12: https://www.google.com/s2/favicons?domain=http://www.caea.gov.cn/ | J12: 政府 | K12: 国务院 | L12: 组成部门 | M12: 999
A13: =表_网址[[#This Row],[1级]]&"-"&表_网址[[#This Row],[2级]]&"-"&表_网址[[#This Row],[3级]]&"-"&表_网址[[#This Row],[级内]] -> 101-11-11-110 | B13: =VLOOKUP(表_网址[[#This Row],[首要关键词]],表_首次要关键词[[首要关键词]:[排序]],2,0) -> 101 | C13: =IF(表_网址[[#This Row],[次要关键词]]="",10,MATCH(表_网址[[#This Row],[次要关键词]],次要关键词,0)+10) -> 11 | D13: =IF(表_网址[[#This Row],[重点关键词]]="",10,MATCH(表_网址[[#This Row],[重点关键词]],OFFSET(重点关键词!$A$1,MATCH($J13,首要关键词,0)*50-48,MATCH($K13,次要关键词,0),重点关键词数量,1),0)+10) -> 11 | E13: =IF(AND(表_网址[[#This Row],[1级]]=B12,表_网址[[#This Row],[2级]]=C12,表_网址[[#This Row],[3级]]=D12),E12+1,101) -> 110 | F13: 国家民族事务委员会 | G13: http://www.neac.gov.cn/ | I13: http://www.neac.gov.cn/favicon.ico | J13: 政府 | K13: 国务院 | L13: 组成部门 | M13: 999 | N13: 999 | P13: 32
A14: =表_网址[[#This Row],[1级]]&"-"&表_网址[[#This Row],[2级]]&"-"&表_网址[[#This Row],[3级]]&"-"&表_网址[[#This Row],[级内]] -> 101-11-11-111 | B14: =VLOOKUP(表_网址[[#This Row],[首要关键词]],表_首次要关键词[[首要关键词]:[排序]],2,0) -> 101 | C14: =IF(表_网址[[#This Row],[次要关键词]]="",10,MATCH(表_网址[[#This Row],[次要关键词]],次要关键词,0)+10) -> 11 | D14: =IF(表_网址[[#This Row],[重点关键词]]="",10,MATCH(表_网址[[#This Row],[重点关键词]],OFFSET(重点关键词!$A$1,MATCH($J14,首要关键词,0)*50-48,MATCH($K14,次要关键词,0),重点关键词数量,1),0)+10) -> 11 | E14: =IF(AND(表_网址[[#This Row],[1级]]=B13,表_网址[[#This Row],[2级]]=C13,表_网址[[#This Row],[3级]]=D13),E13+1,101) -> 111 | F14: 公安部 | G14: https://www.mps.gov.cn/ | I14: https://www.mps.gov.cn/favicon.ico | J14: 政府 | K14: 国务院 | L14: 组成部门 | M14: 999 | N14: 999 | P14: 16
A15: =表_网址[[#This Row],[1级]]&"-"&表_网址[[#This Row],[2级]]&"-"&表_网址[[#This Row],[3级]]&"-"&表_网址[[#This Row],[级内]] -> 101-11-11-112 | B15: =VLOOKUP(表_网址[[#This Row],[首要关键词]],表_首次要关键词[[首要关键词]:[排序]],2,0) -> 101 | C15: =IF(表_网址[[#This Row],[次要关键词]]="",10,MATCH(表_网址[[#This Row],[次要关键词]],次要关键词,0)+10) -> 11 | D15: =IF(表_网址[[#This Row],[重点关键词]]="",10,MATCH(表_网址[[#This Row],[重点关键词]],OFFSET(重点关键词!$A$1,MATCH($J15,首要关键词,0)*50-48,MATCH($K15,次要关键词,0),重点关键词数量,1),0)+10) -> 11 | E15: =IF(AND(表_网址[[#This Row],[1级]]=B14,表_网址[[#This Row],[2级]]=C14,表_网址[[#This Row],[3级]]=D14),E14+1,101) -> 112 | F15: 国家安全部 | J15: 政府 | K15: 国务院 | L15: 组成部门
A16: =表_网址[[#This Row],[1级]]&"-"&表_网址[[#This Row],[2级]]&"-"&表_网址[[#This Row],[3级]]&"-"&表_网址[[#This Row],[级内]] -> 101-11-11-113 | B16: =VLOOKUP(表_网址[[#This Row],[首要关键词]],表_首次要关键词[[首要关键词]:[排序]],2,0) -> 101 | C16: =IF(表_网址[[#This Row],[次要关键词]]="",10,MATCH(表_网址[[#This Row],[次要关键词]],次要关键词,0)+10) -> 11 | D16: =IF(表_网址[[#This Row],[重点关键词]]="",10,MATCH(表_网址[[#This Row],[重点关键词]],OFFSET(重点关键词!$A$1,MATCH($J16,首要关键词,0)*50-48,MATCH($K16,次要关键词,0),重点关键词数量,1),0)+10) -> 11 | E16: =IF(AND(表_网址[[#This Row],[1级]]=B15,表_网址[[#This Row],[2级]]=C15,表_网址[[#This Row],[3级]]=D15),E15+1,101) -> 113 | F16: 民政部 | G16: http://www.mca.gov.cn/ | I16: http://www.mca.gov.cn/favicon.ico | J16: 政府 | K16: 国务院 | L16: 组成部门 | M16: 999 | P16: 16
A17: =表_网址[[#This Row],[1级]]&"-"&表_网址[[#This Row],[2级]]&"-"&表_网址[[#This Row],[3级]]&"-"&表_网址[[#This Row],[级内]] -> 101-11-11-114 | B17: =VLOOKUP(表_网址[[#This Row],[首要关键词]],表_首次要关键词[[首要关键词]:[排序]],2,0) -> 101 | C17: =IF(表_网址[[#This Row],[次要关键词]]="",10,MATCH(表_网址[[#This Row],[次要关键词]],次要关键词,0)+10) -> 11 | D17: =IF(表_网址[[#This Row],[重点关键词]]="",10,MATCH(表_网址[[#This Row],[重点关键词]],OFFSET(重点关键词!$A$1,MATCH($J17,首要关键词,0)*50-48,MATCH($K17,次要关键词,0),重点关键词数量,1),0)+10) -> 11 | E17: =IF(AND(表_网址[[#This Row],[1级]]=B16,表_网址[[#This Row],[2级]]=C16,表_网址[[#This Row],[3级]]=D16),E16+1,101) -> 114 | F17: 司法部 | G17: http://www.moj.gov.cn/ | I17: http://www.legaldaily.com.cn/tongyong/images/2019sfb/2019favicon.ico | J17: 政府 | K17: 国务院 | L17: 组成部门 | M17: 999 | P17: 16
A18: =表_网址[[#This Row],[1级]]&"-"&表_网址[[#This Row],[2级]]&"-"&表_网址[[#This Row],[3级]]&"-"&表_网址[[#This Row],[级内]] -> 101-11-11-115 | B18: =VLOOKUP(表_网址[[#This Row],[首要关键词]],表_首次要关键词[[首要关键词]:[排序]],2,0) -> 101 | C18: =IF(表_网址[[#This Row],[次要关键词]]="",10,MATCH(表_网址[[#This Row],[次要关键词]],次要关键词,0)+10) -> 11 | D18: =IF(表_网址[[#This Row],[重点关键词]]="",10,MATCH(表_网址[[#This Row],[重点关键词]],OFFSET(重点关键词!$A$1,MATCH($J18,首要关键词,0)*50-48,MATCH($K18,次要关键词,0),重点关键词数量,1),0)+10) -> 11 | E18: =IF(AND(表_网址[[#This Row],[1级]]=B17,表_网址[[#This Row],[2级]]=C17,表_网址[[#This Row],[3级]]=D17),E17+1,101) -> 115 | F18: 财政部 | G18: http://www.mof.gov.cn/index.htm | I18: http://www.mof.gov.cn/images/favicon.ico | J18: 政府 | K18: 国务院 | L18: 组成部门 | M18: 999 | P18: 16
A19: =表_网址[[#This Row],[1级]]&"-"&表_网址[[#This Row],[2级]]&"-"&表_网址[[#This Row],[3级]]&"-"&表_网址[[#This Row],[级内]] -> 101-11-11-116 | B19: =VLOOKUP(表_网址[[#This Row],[首要关键词]],表_首次要关键词[[首要关键词]:[排序]],2,0) -> 101 | C19: =IF(表_网址[[#This Row],[次要关键词]]="",10,MATCH(表_网址[[#This Row],[次要关键词]],次要关键词,0)+10) -> 11 | D19: =IF(表_网址[[#This Row],[重点关键词]]="",10,MATCH(表_网址[[#This Row],[重点关键词]],OFFSET(重点关键词!$A$1,MATCH($J19,首要关键词,0)*50-48,MATCH($K19,次要关键词,0),重点关键词数量,1),0)+10) -> 11 | E19: =IF(AND(表_网址[[#This Row],[1级]]=B18,表_网址[[#This Row],[2级]]=C18,表_网址[[#This Row],[3级]]=D18),E18+1,101) -> 116 | F19: 人力资源和社会保障部 | G19: http://www.mohrss.gov.cn/ | I19: https://www.google.com/s2/favicons?domain=http://www.mohrss.gov.cn/ | J19: 政府 | K19: 国务院 | L19: 组成部门 | M19: 999
A20: =表_网址[[#This Row],[1级]]&"-"&表_网址[[#This Row],[2级]]&"-"&表_网址[[#This Row],[3级]]&"-"&表_网址[[#This Row],[级内]] -> 101-11-11-117 | B20: =VLOOKUP(表_网址[[#This Row],[首要关键词]],表_首次要关键词[[首要关键词]:[排序]],2,0) -> 101 | C20: =IF(表_网址[[#This Row],[次要关键词]]="",10,MATCH(表_网址[[#This Row],[次要关键词]],次要关键词,0)+10) -> 11 | D20: =IF(表_网址[[#This Row],[重点关键词]]="",10,MATCH(表_网址[[#This Row],[重点关键词]],OFFSET(重点关键词!$A$1,MATCH($J20,首要关键词,0)*50-48,MATCH($K20,次要关键词,0),重点关键词数量,1),0)+10) -> 11 | E20: =IF(AND(表_网址[[#This Row],[1级]]=B19,表_网址[[#This Row],[2级]]=C19,表_网址[[#This Row],[3级]]=D19),E19+1,101) -> 117 | F20: 自然资源部 | G20: http://www.mnr.gov.cn/ | J20: 政府 | K20: 国务院 | L20: 组成部门
A21: =表_网址[[#This Row],[1级]]&"-"&表_网址[[#This Row],[2级]]&"-"&表_网址[[#This Row],[3级]]&"-"&表_网址[[#This Row],[级内]] -> 101-11-11-118 | B21: =VLOOKUP(表_网址[[#This Row],[首要关键词]],表_首次要关键词[[首要关键词]:[排序]],2,0) -> 101 | C21: =IF(表_网址[[#This Row],[次要关键词]]="",10,MATCH(表_网址[[#This Row],[次要关键词]],次要关键词,0)+10) -> 11 | D21: =IF(表_网址[[#This Row],[重点关键词]]="",10,MATCH(表_网址[[#This Row],[重点关键词]],OFFSET(重点关键词!$A$1,MATCH($J21,首要关键词,0)*50-48,MATCH($K21,次要关键词,0),重点关键词数量,1),0)+10) -> 11 | E21: =IF(AND(表_网址[[#This Row],[1级]]=B20,表_网址[[#This Row],[2级]]=C20,表_网址[[#This Row],[3级]]=D20),E20+1,101) -> 118 | F21: 生态环境部 | G21: http://www.mee.gov.cn/ | I21: http://www.mee.gov.cn/favicon.ico | J21: 政府 | K21: 国务院 | L21: 组成部门 | M21: 999 | N21: 999 | P21: 16
A22: =表_网址[[#This Row],[1级]]&"-"&表_网址[[#This Row],[2级]]&"-"&表_网址[[#This Row],[3级]]&"-"&表_网址[[#This Row],[级内]] -> 101-11-11-119 | B22: =VLOOKUP(表_网址[[#This Row],[首要关键词]],表_首次要关键词[[首要关键词]:[排序]],2,0) -> 101 | C22: =IF(表_网址[[#This Row],[次要关键词]]="",10,MATCH(表_网址[[#This Row],[次要关键词]],次要关键词,0)+10) -> 11 | D22: =IF(表_网址[[#This Row],[重点关键词]]="",10,MATCH(表_网址[[#This Row],[重点关键词]],OFFSET(重点关键词!$A$1,MATCH($J22,首要关键词,0)*50-48,MATCH($K22,次要关键词,0),重点关键词数量,1),0)+10) -> 11 | E22: =IF(AND(表_网址[[#This Row],[1级]]=B21,表_网址[[#This Row],[2级]]=C21,表_网址[[#This Row],[3级]]=D21),E21+1,101) -> 119 | F22: (国家核安全局) | G22: http://nnsa.mee.gov.cn/ | I22: http://nnsa.mee.gov.cn/favicon.ico | J22: 政府 | K22: 国务院 | L22: 组成部门 | M22: 999 | N22: 999 | P22: 16
A23: =表_网址[[#This Row],[1级]]&"-"&表_网址[[#This Row],[2级]]&"-"&表_网址[[#This Row],[3级]]&"-"&表_网址[[#This Row],[级内]] -> 101-11-11-120 | B23: =VLOOKUP(表_网址[[#This Row],[首要关键词]],表_首次要关键词[[首要关键词]:[排序]],2,0) -> 101 | C23: =IF(表_网址[[#This Row],[次要关键词]]="",10,MATCH(表_网址[[#This Row],[次要关键词]],次要关键词,0)+10) -> 11 | D23: =IF(表_网址[[#This Row],[重点关键词]]="",10,MATCH(表_网址[[#This Row],[重点关键词]],OFFSET(重点关键词!$A$1,MATCH($J23,首要关键词,0)*50-48,MATCH($K23,次要关键词,0),重点关键词数量,1),0)+10) -> 11 | E23: =IF(AND(表_网址[[#This Row],[1级]]=B22,表_网址[[#This Row],[2级]]=C22,表_网址[[#This Row],[3级]]=D22),E22+1,101) -> 120 | F23: 住房和城乡建设部 | G23: http://www.mohurd.gov.cn/ | I23: https://www.google.com/s2/favicons?domain=http://www.mohurd.gov.cn/ | J23: 政府 | K23: 国务院 | L23: 组成部门 | M23: 999
A24: =表_网址[[#This Row],[1级]]&"-"&表_网址[[#This Row],[2级]]&"-"&表_网址[[#This Row],[3级]]&"-"&表_网址[[#This Row],[级内]] -> 101-11-11-121 | B24: =VLOOKUP(表_网址[[#This Row],[首要关键词]],表_首次要关键词[[首要关键词]:[排序]],2,0) -> 101 | C24: =IF(表_网址[[#This Row],[次要关键词]]="",10,MATCH(表_网址[[#This Row],[次要关键词]],次要关键词,0)+10) -> 11 | D24: =IF(表_网址[[#This Row],[重点关键词]]="",10,MATCH(表_网址[[#This Row],[重点关键词]],OFFSET(重点关键词!$A$1,MATCH($J24,首要关键词,0)*50-48,MATCH($K24,次要关键词,0),重点关键词数量,1),0)+10) -> 11 | E24: =IF(AND(表_网址[[#This Row],[1级]]=B23,表_网址[[#This Row],[2级]]=C23,表_网址[[#This Row],[3级]]=D23),E23+1,101) -> 121 | F24: 交通运输部 | G24: http://www.mot.gov.cn/ | I24: https://www.google.com/s2/favicons?domain=http://www.mot.gov.cn/ | J24: 政府 | K24: 国务院 | L24: 组成部门 | M24: 999
A25: =表_网址[[#This Row],[1级]]&"-"&表_网址[[#This Row],[2级]]&"-"&表_网址[[#This Row],[3级]]&"-"&表_网址[[#This Row],[级内]] -> 101-11-11-122 | B25: =VLOOKUP(表_网址[[#This Row],[首要关键词]],表_首次要关键词[[首要关键词]:[排序]],2,0) -> 101 | C25: =IF(表_网址[[#This Row],[次要关键词]]="",10,MATCH(表_网址[[#This Row],[次要关键词]],次要关键词,0)+10) -> 11 | D25: =IF(表_网址[[#This Row],[重点关键词]]="",10,MATCH(表_网址[[#This Row],[重点关键词]],OFFSET(重点关键词!$A$1,MATCH($J25,首要关键词,0)*50-48,MATCH($K25,次要关键词,0),重点关键词数量,1),0)+10) -> 11 | E25: =IF(AND(表_网址[[#This Row],[1级]]=B24,表_网址[[#This Row],[2级]]=C24,表_网址[[#This Row],[3级]]=D24),E24+1,101) -> 122 | F25: 水利部 | G25: http://www.mwr.gov.cn/ | I25: http://www.mwr.gov.cn/favicon.ico | J25: 政府 | K25: 国务院 | L25: 组成部门 | M25: 999 | P25: 16
A26: =表_网址[[#This Row],[1级]]&"-"&表_网址[[#This Row],[2级]]&"-"&表_网址[[#This Row],[3级]]&"-"&表_网址[[#This Row],[级内]] -> 101-11-11-123 | B26: =VLOOKUP(表_网址[[#This Row],[首要关键词]],表_首次要关键词[[首要关键词]:[排序]],2,0) -> 101 | C26: =IF(表_网址[[#This Row],[次要关键词]]="",10,MATCH(表_网址[[#This Row],[次要关键词]],次要关键词,0)+10) -> 11 | D26: =IF(表_网址[[#This Row],[重点关键词]]="",10,MATCH(表_网址[[#This Row],[重点关键词]],OFFSET(重点关键词!$A$1,MATCH($J26,首要关键词,0)*50-48,MATCH($K26,次要关键词,0),重点关键词数量,1),0)+10) -> 11 | E26: =IF(AND(表_网址[[#This Row],[1级]]=B25,表_网址[[#This Row],[2级]]=C25,表_网址[[#This Row],[3级]]=D25),E25+1,101) -> 123 | F26: 农业农村部 | G26: http://www.moa.gov.cn/ | I26: http://www.moa.gov.cn/favicon.ico | J26: 政府 | K26: 国务院 | L26: 组成部门 | M26: 999 | P26: 16
A27: =表_网址[[#This Row],[1级]]&"-"&表_网址[[#This Row],[2级]]&"-"&表_网址[[#This Row],[3级]]&"-"&表_网址[[#This Row],[级内]] -> 101-11-11-124 | B27: =VLOOKUP(表_网址[[#This Row],[首要关键词]],表_首次要关键词[[首要关键词]:[排序]],2,0) -> 101 | C27: =IF(表_网址[[#This Row],[次要关键词]]="",10,MATCH(表_网址[[#This Row],[次要关键词]],次要关键词,0)+10) -> 11 | D27: =IF(表_网址[[#This Row],[重点关键词]]="",10,MATCH(表_网址[[#This Row],[重点关键词]],OFFSET(重点关键词!$A$1,MATCH($J27,首要关键词,0)*50-48,MATCH($K27,次要关键词,0),重点关键词数量,1),0)+10) -> 11 | E27: =IF(AND(表_网址[[#This Row],[1级]]=B26,表_网址[[#This Row],[2级]]=C26,表_网址[[#This Row],[3级]]=D26),E26+1,101) -> 124 | F27: 商务部 | G27: http://www.mofcom.gov.cn/ | I27: http://www.mofcom.gov.cn/assets/i/favicon_bak.png | J27: 政府 | K27: 国务院 | L27: 组成部门 | M27: 999 | P27: 32
A28: =表_网址[[#This Row],[1级]]&"-"&表_网址[[#This Row],[2级]]&"-"&表_网址[[#This Row],[3级]]&"-"&表_网址[[#This Row],[级内]] -> 101-11-11-125 | B28: =VLOOKUP(表_网址[[#This Row],[首要关键词]],表_首次要关键词[[首要关键词]:[排序]],2,0) -> 101 | C28: =IF(表_网址[[#This Row],[次要关键词]]="",10,MATCH(表_网址[[#This Row],[次要关键词]],次要关键词,0)+10) -> 11 | D28: =IF(表_网址[[#This Row],[重点关键词]]="",10,MATCH(表_网址[[#This Row],[重点关键词]],OFFSET(重点关键词!$A$1,MATCH($J28,首要关键词,0)*50-48,MATCH($K28,次要关键词,0),重点关键词数量,1),0)+10) -> 11 | E28: =IF(AND(表_网址[[#This Row],[1级]]=B27,表_网址[[#This Row],[2级]]=C27,表_网址[[#This Row],[3级]]=D27),E27+1,101) -> 125 | F28: 文化和旅游部 | G28: https://www.mct.gov.cn/ | I28: https://www.mct.gov.cn/favicon.ico | J28: 政府 | K28: 国务院 | L28: 组成部门 | M28: 999 | N28: 999 | P28: 32
A29: =表_网址[[#This Row],[1级]]&"-"&表_网址[[#This Row],[2级]]&"-"&表_网址[[#This Row],[3级]]&"-"&表_网址[[#This Row],[级内]] -> 101-11-11-126 | B29: =VLOOKUP(表_网址[[#This Row],[首要关键词]],表_首次要关键词[[首要关键词]:[排序]],2,0) -> 101 | C29: =IF(表_网址[[#This Row],[次要关键词]]="",10,MATCH(表_网址[[#This Row],[次要关键词]],次要关键词,0)+10) -> 11 | D29: =IF(表_网址[[#This Row],[重点关键词]]="",10,MATCH(表_网址[[#This Row],[重点关键词]],OFFSET(重点关键词!$A$1,MATCH($J29,首要关键词,0)*50-48,MATCH($K29,次要关键词,0),重点关键词数量,1),0)+10) -> 11 | E29: =IF(AND(表_网址[[#This Row],[1级]]=B28,表_网址[[#This Row],[2级]]=C28,表_网址[[#This Row],[3级]]=D28),E28+1,101) -> 126 | F29: 国家卫生健康委员会 | G29: http://www.nhc.gov.cn/ | I29: https://www.google.com/s2/favicons?domain=http://www.nhc.gov.cn/ | J29: 政府 | K29: 国务院 | L29: 组成部门 | M29: 999
A30: =表_网址[[#This Row],[1级]]&"-"&表_网址[[#This Row],[2级]]&"-"&表_网址[[#This Row],[3级]]&"-"&表_网址[[#This Row],[级内]] -> 101-11-11-127 | B30: =VLOOKUP(表_网址[[#This Row],[首要关键词]],表_首次要关键词[[首要关键词]:[排序]],2,0) -> 101 | C30: =IF(表_网址[[#This Row],[次要关键词]]="",10,MATCH(表_网址[[#This Row],[次要关键词]],次要关键词,0)+10) -> 11 | D30: =IF(表_网址[[#This Row],[重点关键词]]="",10,MATCH(表_网址[[#This Row],[重点关键词]],OFFSET(重点关键词!$A$1,MATCH($J30,首要关键词,0)*50-48,MATCH($K30,次要关键词,0),重点关键词数量,1),0)+10) -> 11 | E30: =IF(AND(表_网址[[#This Row],[1级]]=B29,表_网址[[#This Row],[2级]]=C29,表_网址[[#This Row],[3级]]=D29),E29+1,101) -> 127 | F30: 退役军人事务部 | G30: https://www.mct.gov.cn/ | I30: http://www.mva.gov.cn/favicon.ico | J30: 政府 | K30: 国务院 | L30: 组成部门 | M30: 999 | P30: 16
A31: =表_网址[[#This Row],[1级]]&"-"&表_网址[[#This Row],[2级]]&"-"&表_网址[[#This Row],[3级]]&"-"&表_网址[[#This Row],[级内]] -> 101-11-11-128 | B31: =VLOOKUP(表_网址[[#This Row],[首要关键词]],表_首次要关键词[[首要关键词]:[排序]],2,0) -> 101 | C31: =IF(表_网址[[#This Row],[次要关键词]]="",10,MATCH(表_网址[[#This Row],[次要关键词]],次要关键词,0)+10) -> 11 | D31: =IF(表_网址[[#This Row],[重点关键词]]="",10,MATCH(表_网址[[#This Row],[重点关键词]],OFFSET(重点关键词!$A$1,MATCH($J31,首要关键词,0)*50-48,MATCH($K31,次要关键词,0),重点关键词数量,1),0)+10) -> 11 | E31: =IF(AND(表_网址[[#This Row],[1级]]=B30,表_网址[[#This Row],[2级]]=C30,表_网址[[#This Row],[3级]]=D30),E30+1,101) -> 128 | F31: 应急管理部 | G31: http://www.mem.gov.cn/ | I31: http://www.mem.gov.cn/image/favicon.ico | J31: 政府 | K31: 国务院 | L31: 组成部门 | M31: 999 | N31: 999 | P31: 64
A32: =表_网址[[#This Row],[1级]]&"-"&表_网址[[#This Row],[2级]]&"-"&表_网址[[#This Row],[3级]]&"-"&表_网址[[#This Row],[级内]] -> 101-11-11-129 | B32: =VLOOKUP(表_网址[[#This Row],[首要关键词]],表_首次要关键词[[首要关键词]:[排序]],2,0) -> 101 | C32: =IF(表_网址[[#This Row],[次要关键词]]="",10,MATCH(表_网址[[#This Row],[次要关键词]],次要关键词,0)+10) -> 11 | D32: =IF(表_网址[[#This Row],[重点关键词]]="",10,MATCH(表_网址[[#This Row],[重点关键词]],OFFSET(重点关键词!$A$1,MATCH($J32,首要关键词,0)*50-48,MATCH($K32,次要关键词,0),重点关键词数量,1),0)+10) -> 11 | E32: =IF(AND(表_网址[[#This Row],[1级]]=B31,表_网址[[#This Row],[2级]]=C31,表_网址[[#This Row],[3级]]=D31),E31+1,101) -> 129 | F32: 中国人民银行 | G32: http://www.pbc.gov.cn/ | I32: http://www.pbc.gov.cn/rmyh/uiFramework/commonResource/image/logo.ico | J32: 政府 | K32: 国务院 | L32: 组成部门 | M32: 999 | P32: 16
A33: =表_网址[[#This Row],[1级]]&"-"&表_网址[[#This Row],[2级]]&"-"&表_网址[[#This Row],[3级]]&"-"&表_网址[[#This Row],[级内]] -> 101-11-11-130 | B33: =VLOOKUP(表_网址[[#This Row],[首要关键词]],表_首次要关键词[[首要关键词]:[排序]],2,0) -> 101 | C33: =IF(表_网址[[#This Row],[次要关键词]]="",10,MATCH(表_网址[[#This Row],[次要关键词]],次要关键词,0)+10) -> 11 | D33: =IF(表_网址[[#This Row],[重点关键词]]="",10,MATCH(表_网址[[#This Row],[重点关键词]],OFFSET(重点关键词!$A$1,MATCH($J33,首要关键词,0)*50-48,MATCH($K33,次要关键词,0),重点关键词数量,1),0)+10) -> 11 | E33: =IF(AND(表_网址[[#This Row],[1级]]=B32,表_网址[[#This Row],[2级]]=C32,表_网址[[#This Row],[3级]]=D32),E32+1,101) -> 130 | F33: 审计署 | G33: http://www.audit.gov.cn/ | I33: https://www.google.com/s2/favicons?domain=http://www.audit.gov.cn/ | J33: 政府 | K33: 国务院 | L33: 组成部门 | M33: 999
A34: =表_网址[[#This Row],[1级]]&"-"&表_网址[[#This Row],[2级]]&"-"&表_网址[[#This Row],[3级]]&"-"&表_网址[[#This Row],[级内]] -> 101-11-12-101 | B34: =VLOOKUP(表_网址[[#This Row],[首要关键词]],表_首次要关键词[[首要关键词]:[排序]],2,0) -> 101 | C34: =IF(表_网址[[#This Row],[次要关键词]]="",10,MATCH(表_网址[[#This Row],[次要关键词]],次要关键词,0)+10) -> 11 | D34: =IF(表_网址[[#This Row],[重点关键词]]="",10,MATCH(表_网址[[#This Row],[重点关键词]],OFFSET(重点关键词!$A$1,MATCH($J34,首要关键词,0)*50-48,MATCH($K34,次要关键词,0),重点关键词数量,1),0)+10) -> 12 | E34: =IF(AND(表_网址[[#This Row],[1级]]=B33,表_网址[[#This Row],[2级]]=C33,表_网址[[#This Row],[3级]]=D33),E33+1,101) -> 101 | F34: 国有资产监督管理委员会 | G34: http://www.sasac.gov.cn/ | H34: 国务院国有资产监督管理委员会 | I34: http://www.sasac.gov.cn/dbsource/11869722/11869731.jpg | J34: 政府 | K34: 国务院 | L34: 直属特设机构 | M34: 999 | P34: 30
A35: =表_网址[[#This Row],[1级]]&"-"&表_网址[[#This Row],[2级]]&"-"&表_网址[[#This Row],[3级]]&"-"&表_网址[[#This Row],[级内]] -> 101-11-13-101 | B35: =VLOOKUP(表_网址[[#This Row],[首要关键词]],表_首次要关键词[[首要关键词]:[排序]],2,0) -> 101 | C35: =IF(表_网址[[#This Row],[次要关键词]]="",10,MATCH(表_网址[[#This Row],[次要关键词]],次要关键词,0)+10) -> 11 | D35: =IF(表_网址[[#This Row],[重点关键词]]="",10,MATCH(表_网址[[#This Row],[重点关键词]],OFFSET(重点关键词!$A$1,MATCH($J35,首要关键词,0)*50-48,MATCH($K35,次要关键词,0),重点关键词数量,1),0)+10) -> 13 | E35: =IF(AND(表_网址[[#This Row],[1级]]=B34,表_网址[[#This Row],[2级]]=C34,表_网址[[#This Row],[3级]]=D34),E34+1,101) -> 101 | F35: 海关总署 | G35: http://www.customs.gov.cn/ | I35: https://www.google.com/s2/favicons?domain=http://www.customs.gov.cn/ | J35: 政府 | K35: 国务院 | L35: 直属机构 | M35: 999 | N35: 999
A36: =表_网址[[#This Row],[1级]]&"-"&表_网址[[#This Row],[2级]]&"-"&表_网址[[#This Row],[3级]]&"-"&表_网址[[#This Row],[级内]] -> 101-11-13-102 | B36: =VLOOKUP(表_网址[[#This Row],[首要关键词]],表_首次要关键词[[首要关键词]:[排序]],2,0) -> 101 | C36: =IF(表_网址[[#This Row],[次要关键词]]="",10,MATCH(表_网址[[#This Row],[次要关键词]],次要关键词,0)+10) -> 11 | D36: =IF(表_网址[[#This Row],[重点关键词]]="",10,MATCH(表_网址[[#This Row],[重点关键词]],OFFSET(重点关键词!$A$1,MATCH($J36,首要关键词,0)*50-48,MATCH($K36,次要关键词,0),重点关键词数量,1),0)+10) -> 13 | E36: =IF(AND(表_网址[[#This Row],[1级]]=B35,表_网址[[#This Row],[2级]]=C35,表_网址[[#This Row],[3级]]=D35),E35+1,101) -> 102 | F36: 国家税务总局 | G36: http://www.chinatax.gov.cn/ | I36: https://www.google.com/s2/favicons?domain=http://www.chinatax.gov.cn/ | J36: 政府 | K36: 国务院 | L36: 直属机构 | M36: 999
A37: =表_网址[[#This Row],[1级]]&"-"&表_网址[[#This Row],[2级]]&"-"&表_网址[[#This Row],[3级]]&"-"&表_网址[[#This Row],[级内]] -> 101-11-13-103 | B37: =VLOOKUP(表_网址[[#This Row],[首要关键词]],表_首次要关键词[[首要关键词]:[排序]],2,0) -> 101 | C37: =IF(表_网址[[#This Row],[次要关键词]]="",10,MATCH(表_网址[[#This Row],[次要关键词]],次要关键词,0)+10) -> 11 | D37: =IF(表_网址[[#This Row],[重点关键词]]="",10,MATCH(表_网址[[#This Row],[重点关键词]],OFFSET(重点关键词!$A$1,MATCH($J37,首要关键词,0)*50-48,MATCH($K37,次要关键词,0),重点关键词数量,1),0)+10) -> 13 | E37: =IF(AND(表_网址[[#This Row],[1级]]=B36,表_网址[[#This Row],[2级]]=C36,表_网址[[#This Row],[3级]]=D36),E36+1,101) -> 103 | F37: 国家市场监督管理总局 | G37: http://www.samr.gov.cn/ | I37: http://www.samr.gov.cn/favicon.ico | J37: 政府 | K37: 国务院 | L37: 直属机构 | M37: 999 | P37: 16
A38: =表_网址[[#This Row],[1级]]&"-"&表_网址[[#This Row],[2级]]&"-"&表_网址[[#This Row],[3级]]&"-"&表_网址[[#This Row],[级内]] -> 101-11-13-104 | B38: =VLOOKUP(表_网址[[#This Row],[首要关键词]],表_首次要关键词[[首要关键词]:[排序]],2,0) -> 101 | C38: =IF(表_网址[[#This Row],[次要关键词]]="",10,MATCH(表_网址[[#This Row],[次要关键词]],次要关键词,0)+10) -> 11 | D38: =IF(表_网址[[#This Row],[重点关键词]]="",10,MATCH(表_网址[[#This Row],[重点关键词]],OFFSET(重点关键词!$A$1,MATCH($J38,首要关键词,0)*50-48,MATCH($K38,次要关键词,0),重点关键词数量,1),0)+10) -> 13 | E38: =IF(AND(表_网址[[#This Row],[1级]]=B37,表_网址[[#This Row],[2级]]=C37,表_网址[[#This Row],[3级]]=D37),E37+1,101) -> 104 | F38: (国家认证认可监督管理委员会) | G38: http://www.cnca.gov.cn/ | I38: http://www.cnca.gov.cn/favicon.ico | J38: 政府 | K38: 国务院 | L38: 直属机构 | M38: 999 | P38: 16
A39: =表_网址[[#This Row],[1级]]&"-"&表_网址[[#This Row],[2级]]&"-"&表_网址[[#This Row],[3级]]&"-"&表_网址[[#This Row],[级内]] -> 101-11-13-105 | B39: =VLOOKUP(表_网址[[#This Row],[首要关键词]],表_首次要关键词[[首要关键词]:[排序]],2,0) -> 101 | C39: =IF(表_网址[[#This Row],[次要关键词]]="",10,MATCH(表_网址[[#This Row],[次要关键词]],次要关键词,0)+10) -> 11 | D39: =IF(表_网址[[#This Row],[重点关键词]]="",10,MATCH(表_网址[[#This Row],[重点关键词]],OFFSET(重点关键词!$A$1,MATCH($J39,首要关键词,0)*50-48,MATCH($K39,次要关键词,0),重点关键词数量,1),0)+10) -> 13 | E39: =IF(AND(表_网址[[#This Row],[1级]]=B38,表_网址[[#This Row],[2级]]=C38,表_网址[[#This Row],[3级]]=D38),E38+1,101) -> 105 | F39: (国家标准化管理委员会) | G39: http://www.sac.gov.cn/ | I39: http://www.sac.gov.cn/favicon.ico | J39: 政府 | K39: 国务院 | L39: 直属机构 | M39: 999 | P39: 16
A40: =表_网址[[#This Row],[1级]]&"-"&表_网址[[#This Row],[2级]]&"-"&表_网址[[#This Row],[3级]]&"-"&表_网址[[#This Row],[级内]] -> 101-11-13-106 | B40: =VLOOKUP(表_网址[[#This Row],[首要关键词]],表_首次要关键词[[首要关键词]:[排序]],2,0) -> 101 | C40: =IF(表_网址[[#This Row],[次要关键词]]="",10,MATCH(表_网址[[#This Row],[次要关键词]],次要关键词,0)+10) -> 11 | D40: =IF(表_网址[[#This Row],[重点关键词]]="",10,MATCH(表_网址[[#This Row],[重点关键词]],OFFSET(重点关键词!$A$1,MATCH($J40,首要关键词,0)*50-48,MATCH($K40,次要关键词,0),重点关键词数量,1),0)+10) -> 13 | E40: =IF(AND(表_网址[[#This Row],[1级]]=B39,表_网址[[#This Row],[2级]]=C39,表_网址[[#This Row],[3级]]=D39),E39+1,101) -> 106 | F40: 国家广播电视总局 | G40: http://www.nrta.gov.cn/ | I40: http://www.nrta.gov.cn/favicon.ico | J40: 政府 | K40: 国务院 | L40: 直属机构 | M40: 999 | P40: 32
...

Sheet Sheet7
A1: 序号 | B1: 1级 | C1: 2级 | D1: 3级 | E1: 级内 | F1: 简称 | G1: 网址 | H1: 描述title | I1: 图标地址 | J1: 首要关键词 | K1: 次要关键词 | L1: 重点关键词 | M1: 判断网址 | N1: 判断图片 | O1: 其他标签 | P1: 图标大小 | Q1: 备案/未备案 | R1: 经营性/非经营性
A2: 101-11-10-101 | B2: 101 | C2: 11 | D2: 10 | E2: 101 | F2: 中国政府网 | G2: http://www.gov.cn/ | H2: 中华人民共和国中央人民政府 | I2: http://www.gov.cn/govweb/xhtml/favicon.ico | J2: 政府 | K2: 国务院 | M2: 999 | N2: 999 | P2: 16
A3: 101-11-10-102 | B3: 101 | C3: 11 | D3: 10 | E3: 102 | F3: 国务院办公厅 | J3: 政府 | K3: 国务院
B4: 101 | C4: 11 | D4: 12 | F4: 外交部 | G4: https://www.fmprc.gov.cn/web/ | I4: https://www.google.com/s2/favicons?domain=https://www.fmprc.gov.cn/web/ | J4: 政府 | K4: 国务院 | L4: 组成部门 | M4: 999
B5: 101 | C5: 11 | D5: 12 | F5: 国防部 | G5: http://www.mod.gov.cn/ | I5: http://www.mod.gov.cn/favicon.ico | J5: 政府 | K5: 国务院 | L5: 组成部门 | M5: 999 | P5: 256
B6: 101 | C6: 11 | D6: 12 | F6: 国家发展和改革委员会 | G6: https://www.ndrc.gov.cn/ | I6: https://www.google.com/s2/favicons?domain=https://www.ndrc.gov.cn/ | J6: 政府 | K6: 国务院 | L6: 组成部门 | M6: 999
B7: 101 | C7: 11 | D7: 12 | F7: 教育部 | G7: http://www.moe.gov.cn/ | I7: http://www.moe.gov.cn/favorite.ico | J7: 政府 | K7: 国务院 | L7: 组成部门 | M7: 999 | P7: 16
B8: 101 | C8: 11 | D8: 12 | F8: (国家语言文字工作委员会) | G8: http://www.moe.gov.cn/jyb_sy/China_Language/ | I8: http://www.moe.gov.cn/favorite.ico | J8: 政府 | K8: 国务院 | L8: 组成部门 | M8: 999 | P8: 16
B9: 101 | C9: 11 | D9: 12 | F9: 科学技术部 | G9: http://www.most.gov.cn/ | I9: http://www.most.gov.cn/favicon.ico | J9: 政府 | K9: 国务院 | L9: 组成部门 | M9: 999 | P9: 16
B10: 101 | C10: 11 | D10: 12 | F10: 工业和信息化部 | G10: https://www.miit.gov.cn/ | I10: https://www.miit.gov.cn/favicon.ico | J10: 政府 | K10: 国务院 | L10: 组成部门 | M10: 999 | N10: 999 | P10: 32
B11: 101 | C11: 11 | D11: 12 | F11: (国家航天局) | G11: http://www.cnsa.gov.cn/ | I11: https://www.google.com/s2/favicons?domain=http://www.cnsa.gov.cn/ | J11: 政府 | K11: 国务院 | L11: 组成部门 | M11: 999
B12: 101 | C12: 11 | D12: 12 | F12: (国家原子能机构) | G12: http://www.caea.gov.cn/ | I12: https://www.google.com/s2/favicons?domain=http://www.caea.gov.cn/ | J12: 政府 | K12: 国务院 | L12: 组成部门 | M12: 999
B13: 101 | C13: 11 | D13: 12 | F13: 国家民族事务委员会 | G13: http://www.neac.gov.cn/ | I13: http://www.neac.gov.cn/favicon.ico | J13: 政府 | K13: 国务院 | L13: 组成部门 | M13: 999 | N13: 999 | P13: 32
B14: 101 | C14: 11 | D14: 12 | F14: 公安部 | G14: https://www.mps.gov.cn/ | I14: https://www.mps.gov.cn/favicon.ico | J14: 政府 | K14: 国务院 | L14: 组成部门 | M14: 999 | N14: 999 | P14: 16
B15: 101 | C15: 11 | D15: 12 | F15: 国家安全部 | J15: 政府 | K15: 国务院 | L15: 组成部门
B16: 101 | C16: 11 | D16: 12 | F16: 民政部 | G16: http://www.mca.gov.cn/ | I16: http://www.mca.gov.cn/favicon.ico | J16: 政府 | K16: 国务院 | L16: 组成部门 | M16: 999 | P16: 16
B17: 101 | C17: 11 | D17: 12 | F17: 司法部 | G17: http://www.moj.gov.cn/ | I17: http://www.legaldaily.com.cn/tongyong/images/2019sfb/2019favicon.ico | J17: 政府 | K17: 国务院 | L17: 组成部门 | M17: 999 | P17: 16
B18: 101 | C18: 11 | D18: 12 | F18: 财政部 | G18: http://www.mof.gov.cn/index.htm | I18: http://www.mof.gov.cn/images/favicon.ico | J18: 政府 | K18: 国务院 | L18: 组成部门 | M18: 999 | P18: 16
B19: 101 | C19: 11 | D19: 12 | F19: 人力资源和社会保障部 | G19: http://www.mohrss.gov.cn/ | I19: https://www.google.com/s2/favicons?domain=http://www.mohrss.gov.cn/ | J19: 政府 | K19: 国务院 | L19: 组成部门 | M19: 999
B20: 101 | C20: 11 | D20: 12 | F20: 自然资源部 | G20: http://www.mnr.gov.cn/ | J20: 政府 | K20: 国务院 | L20: 组成部门
B21: 101 | C21: 11 | D21: 12 | F21: 生态环境部 | G21: http://www.mee.gov.cn/ | I21: http://www.mee.gov.cn/favicon.ico | J21: 政府 | K21: 国务院 | L21: 组成部门 | M21: 999 | N21: 999 | P21: 16
B22: 101 | C22: 11 | D22: 12 | F22: (国家核安全局) | G22: http://nnsa.mee.gov.cn/ | I22: http://nnsa.mee.gov.cn/favicon.ico | J22: 政府 | K22: 国务院 | L22: 组成部门 | M22: 999 | N22: 999 | P22: 16
B23: 101 | C23: 11 | D23: 12 | F23: 住房和城乡建设部 | G23: http://www.mohurd.gov.cn/ | I23: https://www.google.com/s2/favicons?domain=http://www.mohurd.gov.cn/ | J23: 政府 | K23: 国务院 | L23: 组成部门 | M23: 999
B24: 101 | C24: 11 | D24: 12 | F24: 交通运输部 | G24: http://www.mot.gov.cn/ | I24: https://www.google.com/s2/favicons?domain=http://www.mot.gov.cn/ | J24: 政府 | K24: 国务院 | L24: 组成部门 | M24: 999
B25: 101 | C25: 11 | D25: 12 | F25: 水利部 | G25: http://www.mwr.gov.cn/ | I25: http://www.mwr.gov.cn/favicon.ico | J25: 政府 | K25: 国务院 | L25: 组成部门 | M25: 999 | P25: 16
B26: 101 | C26: 11 | D26: 12 | F26: 农业农村部 | G26: http://www.moa.gov.cn/ | I26: http://www.moa.gov.cn/favicon.ico | J26: 政府 | K26: 国务院 | L26: 组成部门 | M26: 999 | P26: 16
B27: 101 | C27: 11 | D27: 12 | F27: 商务部 | G27: http://www.mofcom.gov.cn/ | I27: http://www.mofcom.gov.cn/assets/i/favicon_bak.png | J27: 政府 | K27: 国务院 | L27: 组成部门 | M27: 999 | P27: 32
B28: 101 | C28: 11 | D28: 12 | F28: 文化和旅游部 | G28: https://www.mct.gov.cn/ | I28: https://www.mct.gov.cn/favicon.ico | J28: 政府 | K28: 国务院 | L28: 组成部门 | M28: 999 | N28: 999 | P28: 32
B29: 101 | C29: 11 | D29: 12 | F29: 国家卫生健康委员会 | G29: http://www.nhc.gov.cn/ | I29: https://www.google.com/s2/favicons?domain=http://www.nhc.gov.cn/ | J29: 政府 | K29: 国务院 | L29: 组成部门 | M29: 999
B30: 101 | C30: 11 | D30: 12 | F30: 退役军人事务部 | G30: https://www.mct.gov.cn/ | I30: http://www.mva.gov.cn/favicon.ico | J30: 政府 | K30: 国务院 | L30: 组成部门 | M30: 999 | P30: 16
B31: 101 | C31: 11 | D31: 12 | F31: 应急管理部 | G31: http://www.mem.gov.cn/ | I31: http://www.mem.gov.cn/image/favicon.ico | J31: 政府 | K31: 国务院 | L31: 组成部门 | M31: 999 | N31: 999 | P31: 64
B32: 101 | C32: 11 | D32: 12 | F32: 中国人民银行 | G32: http://www.pbc.gov.cn/ | I32: http://www.pbc.gov.cn/rmyh/uiFramework/commonResource/image/logo.ico | J32: 政府 | K32: 国务院 | L32: 组成部门 | M32: 999 | P32: 16
B33: 101 | C33: 11 | D33: 12 | F33: 审计署 | G33: http://www.audit.gov.cn/ | I33: https://www.google.com/s2/favicons?domain=http://www.audit.gov.cn/ | J33: 政府 | K33: 国务院 | L33: 组成部门 | M33: 999
B34: 101 | C34: 11 | D34: 13 | F34: 国有资产监督管理委员会 | G34: http://www.sasac.gov.cn/ | H34: 国务院国有资产监督管理委员会 | I34: http://www.sasac.gov.cn/dbsource/11869722/11869731.jpg | J34: 政府 | K34: 国务院 | L34: 直属特设机构 | M34: 999 | P34: 30
B35: 101 | C35: 11 | D35: 14 | F35: 海关总署 | G35: http://www.customs.gov.cn/ | I35: https://www.google.com/s2/favicons?domain=http://www.customs.gov.cn/ | J35: 政府 | K35: 国务院 | L35: 直属机构 | M35: 999 | N35: 999
B36: 101 | C36: 11 | D36: 14 | F36: 国家税务总局 | G36: http://www.chinatax.gov.cn/ | I36: https://www.google.com/s2/favicons?domain=http://www.chinatax.gov.cn/ | J36: 政府 | K36: 国务院 | L36: 直属机构 | M36: 999
B37: 101 | C37: 11 | D37: 14 | F37: 国家市场监督管理总局 | G37: http://www.samr.gov.cn/ | I37: http://www.samr.gov.cn/favicon.ico | J37: 政府 | K37: 国务院 | L37: 直属机构 | M37: 999 | P37: 16
B38: 101 | C38: 11 | D38: 14 | F38: (国家认证认可监督管理委员会) | G38: http://www.cnca.gov.cn/ | I38: http://www.cnca.gov.cn/favicon.ico | J38: 政府 | K38: 国务院 | L38: 直属机构 | M38: 999 | P38: 16
B39: 101 | C39: 11 | D39: 14 | F39: (国家标准化管理委员会) | G39: http://www.sac.gov.cn/ | I39: http://www.sac.gov.cn/favicon.ico | J39: 政府 | K39: 国务院 | L39: 直属机构 | M39: 999 | P39: 16
B40: 101 | C40: 11 | D40: 14 | F40: 国家广播电视总局 | G40: http://www.nrta.gov.cn/ | I40: http://www.nrta.gov.cn/favicon.ico | J40: 政府 | K40: 国务院 | L40: 直属机构 | M40: 999 | P40: 32
...

Sheet Sheet2
A1: - | B1: 一级 | C1: 二级 | D1: 三级 | E1: 级内 | F1: 简称 | G1: 网址 | H1: 描述title | I1: https://www.google.com/s2/favicons?domain= | J1: 主要关键词 | K1: 次要关键词 | L1: 关键词 | N1: 判断网址 | O1: 判断图片 | P1: 其他标签 | Q1: 图标大小 | R1: 备案/未备案 | S1: 经营性/非经营性
A2: #REF! | B2: 101 | C2: #REF! | D2: #VALUE! | E2: 10001 | F2: 中国政府网 | G2: http://www.gov.cn/ | H2: 中华人民共和国中央人民政府 | I2: http://www.gov.cn/govweb/xhtml/favicon.ico | J2: 政府 | N2: 999 | O2: 999 | Q2: 16
A3: #REF! | B3: 101 | C3: #REF! | D3: #VALUE! | E3: 10002 | F3: 国务院办公厅 | J3: 政府 | K3: 国务院
A4: #REF! | B4: 101 | C4: #REF! | D4: #VALUE! | E4: 10003 | F4: 外交部 | G4: https://www.fmprc.gov.cn/web/ | I4: https://www.google.com/s2/favicons?domain=https://www.fmprc.gov.cn/web/ | J4: 政府 | K4: 国务院 | L4: 组成部门 | N4: 999
A5: #REF! | B5: 101 | C5: #REF! | D5: #VALUE! | E5: 10004 | F5: 国防部 | G5: http://www.mod.gov.cn/ | I5: http://www.mod.gov.cn/favicon.ico | J5: 政府 | K5: 国务院 | L5: 组成部门 | N5: 999 | Q5: 256
A6: #REF! | B6: 101 | C6: #REF! | D6: #VALUE! | E6: 10005 | F6: 国家发展和改革委员会 | G6: https://www.ndrc.gov.cn/ | I6: https://www.google.com/s2/favicons?domain=https://www.ndrc.gov.cn/ | J6: 政府 | K6: 国务院 | L6: 组成部门 | N6: 999
A7: #REF! | B7: 101 | C7: #REF! | D7: #VALUE! | E7: 10006 | F7: 教育部 | G7: http://www.moe.gov.cn/ | I7: http://www.moe.gov.cn/favorite.ico | J7: 政府 | K7: 国务院 | L7: 组成部门 | N7: 999 | Q7: 16
A8: #REF! | B8: 101 | C8: #REF! | D8: #VALUE! | E8: 10007 | F8: (国家语言文字工作委员会) | G8: http://www.moe.gov.cn/jyb_sy/China_Language/ | I8: http://www.moe.gov.cn/favorite.ico | J8: 政府 | K8: 国务院 | L8: 组成部门 | N8: 999 | Q8: 16
A9: #REF! | B9: 101 | C9: #REF! | D9: #VALUE! | E9: 10008 | F9: 科学技术部 | G9: http://www.most.gov.cn/ | I9: http://www.most.gov.cn/favicon.ico | J9: 政府 | K9: 国务院 | L9: 组成部门 | N9: 999 | Q9: 16
A10: #REF! | B10: 101 | C10: #REF! | D10: #VALUE! | E10: 10009 | F10: 工业和信息化部 | G10: https://www.miit.gov.cn/ | I10: https://www.miit.gov.cn/favicon.ico | J10: 政府 | K10: 国务院 | L10: 组成部门 | N10: 999 | O10: 999 | Q10: 32
A11: #REF! | B11: 101 | C11: #REF! | D11: #VALUE! | E11: 10010 | F11: (国家航天局) | G11: http://www.cnsa.gov.cn/ | I11: https://www.google.com/s2/favicons?domain=http://www.cnsa.gov.cn/ | J11: 政府 | K11: 国务院 | L11: 组成部门 | N11: 999
A12: #REF! | B12: 101 | C12: #REF! | D12: #VALUE! | E12: 10011 | F12: (国家原子能机构) | G12: http://www.caea.gov.cn/ | I12: https://www.google.com/s2/favicons?domain=http://www.caea.gov.cn/ | J12: 政府 | K12: 国务院 | L12: 组成部门 | N12: 999
A13: #REF! | B13: 101 | C13: #REF! | D13: #VALUE! | E13: 10012 | F13: 国家民族事务委员会 | G13: http://www.neac.gov.cn/ | I13: http://www.neac.gov.cn/favicon.ico | J13: 政府 | K13: 国务院 | L13: 组成部门 | N13: 999 | O13: 999 | Q13: 32
A14: #REF! | B14: 101 | C14: #REF! | D14: #VALUE! | E14: 10013 | F14: 公安部 | G14: https://www.mps.gov.cn/ | I14: https://www.mps.gov.cn/favicon.ico | J14: 政府 | K14: 国务院 | L14: 组成部门 | N14: 999 | O14: 999 | Q14: 16
A15: #REF! | B15: 101 | C15: #REF! | D15: #VALUE! | E15: 10014 | F15: 国家安全部 | J15: 政府 | K15: 国务院 | L15: 组成部门
A16: #REF! | B16: 101 | C16: #REF! | D16: #VALUE! | E16: 10015 | F16: 民政部 | G16: http://www.mca.gov.cn/ | I16: http://www.mca.gov.cn/favicon.ico | J16: 政府 | K16: 国务院 | L16: 组成部门 | N16: 999 | Q16: 16
A17: #REF! | B17: 101 | C17: #REF! | D17: #VALUE! | E17: 10016 | F17: 司法部 | G17: http://www.moj.gov.cn/ | I17: http://www.legaldaily.com.cn/tongyong/images/2019sfb/2019favicon.ico | J17: 政府 | K17: 国务院 | L17: 组成部门 | N17: 999 | Q17: 16
A18: #REF! | B18: 101 | C18: #REF! | D18: #VALUE! | E18: 10017 | F18: 财政部 | G18: http://www.mof.gov.cn/index.htm | I18: http://www.mof.gov.cn/images/favicon.ico | J18: 政府 | K18: 国务院 | L18: 组成部门 | N18: 999 | Q18: 16
A19: #REF! | B19: 101 | C19: #REF! | D19: #VALUE! | E19: 10018 | F19: 人力资源和社会保障部 | G19: http://www.mohrss.gov.cn/ | I19: https://www.google.com/s2/favicons?domain=http://www.mohrss.gov.cn/ | J19: 政府 | K19: 国务院 | L19: 组成部门 | N19: 999
A20: #REF! | B20: 101 | C20: #REF! | D20: #VALUE! | E20: 10019 | F20: 自然资源部 | G20: http://www.mnr.gov.cn/ | J20: 政府 | K20: 国务院 | L20: 组成部门
A21: #REF! | B21: 101 | C21: #REF! | D21: #VALUE! | E21: 10020 | F21: 生态环境部 | G21: http://www.mee.gov.cn/ | I21: http://www.mee.gov.cn/favicon.ico | J21: 政府 | K21: 国务院 | L21: 组成部门 | N21: 999 | O21: 999 | Q21: 16
A22: #REF! | B22: 101 | C22: #REF! | D22: #VALUE! | E22: 10021 | F22: (国家核安全局) | G22: http://nnsa.mee.gov.cn/ | I22: http://nnsa.mee.gov.cn/favicon.ico | J22: 政府 | K22: 国务院 | L22: 组成部门 | N22: 999 | O22: 999 | Q22: 16
A23: #REF! | B23: 101 | C23: #REF! | D23: #VALUE! | E23: 10022 | F23: 住房和城乡建设部 | G23: http://www.mohurd.gov.cn/ | I23: https://www.google.com/s2/favicons?domain=http://www.mohurd.gov.cn/ | J23: 政府 | K23: 国务院 | L23: 组成部门 | N23: 999
A24: #REF! | B24: 101 | C24: #REF! | D24: #VALUE! | E24: 10023 | F24: 交通运输部 | G24: http://www.mot.gov.cn/ | I24: https://www.google.com/s2/favicons?domain=http://www.mot.gov.cn/ | J24: 政府 | K24: 国务院 | L24: 组成部门 | N24: 999
A25: #REF! | B25: 101 | C25: #REF! | D25: #VALUE! | E25: 10024 | F25: 水利部 | G25: http://www.mwr.gov.cn/ | I25: http://www.mwr.gov.cn/favicon.ico | J25: 政府 | K25: 国务院 | L25: 组成部门 | N25: 999 | Q25: 16
A26: #REF! | B26: 101 | C26: #REF! | D26: #VALUE! | E26: 10025 | F26: 农业农村部 | G26: http://www.moa.gov.cn/ | I26: http://www.moa.gov.cn/favicon.ico | J26: 政府 | K26: 国务院 | L26: 组成部门 | N26: 999 | Q26: 16
A27: #REF! | B27: 101 | C27: #REF! | D27: #VALUE! | E27: 10026 | F27: 商务部 | G27: http://www.mofcom.gov.cn/ | I27: http://www.mofcom.gov.cn/assets/i/favicon_bak.png | J27: 政府 | K27: 国务院 | L27: 组成部门 | N27: 999 | Q27: 32
A28: #REF! | B28: 101 | C28: #REF! | D28: #VALUE! | E28: 10027 | F28: 文化和旅游部 | G28: https://www.mct.gov.cn/ | I28: https://www.mct.gov.cn/favicon.ico | J28: 政府 | K28: 国务院 | L28: 组成部门 | N28: 999 | O28: 999 | Q28: 32
A29: #REF! | B29: 101 | C29: #REF! | D29: #VALUE! | E29: 10028 | F29: 国家卫生健康委员会 | G29: http://www.nhc.gov.cn/ | I29: https://www.google.com/s2/favicons?domain=http://www.nhc.gov.cn/ | J29: 政府 | K29: 国务院 | L29: 组成部门 | N29: 999
A30: #REF! | B30: 101 | C30: #REF! | D30: #VALUE! | E30: 10029 | F30: 退役军人事务部 | G30: https://www.mct.gov.cn/ | I30: http://www.mva.gov.cn/favicon.ico | J30: 政府 | K30: 国务院 | L30: 组成部门 | N30: 999 | Q30: 16
A31: #REF! | B31: 101 | C31: #REF! | D31: #VALUE! | E31: 10030 | F31: 应急管理部 | G31: http://www.mem.gov.cn/ | I31: http://www.mem.gov.cn/image/favicon.ico | J31: 政府 | K31: 国务院 | L31: 组成部门 | N31: 999 | O31: 999 | Q31: 64
A32: #REF! | B32: 101 | C32: #REF! | D32: #VALUE! | E32: 10031 | F32: 中国人民银行 | G32: http://www.pbc.gov.cn/ | I32: http://www.pbc.gov.cn/rmyh/uiFramework/commonResource/image/logo.ico | J32: 政府 | K32: 国务院 | L32: 组成部门 | N32: 999 | Q32: 16
A33: #REF! | B33: 101 | C33: #REF! | D33: #VALUE! | E33: 10032 | F33: 审计署 | G33: http://www.audit.gov.cn/ | I33: https://www.google.com/s2/favicons?domain=http://www.audit.gov.cn/ | J33: 政府 | K33: 国务院 | L33: 组成部门 | N33: 999
A34: #REF! | B34: 101 | C34: #REF! | D34: #VALUE! | E34: 10033 | F34: 国有资产监督管理委员会 | G34: http://www.sasac.gov.cn/ | H34: 国务院国有资产监督管理委员会 | I34: http://www.sasac.gov.cn/dbsource/11869722/11869731.jpg | J34: 政府 | K34: 国务院 | L34: 直属特设机构 | N34: 999 | Q34: 30
A35: #REF! | B35: 101 | C35: #REF! | D35: #VALUE! | E35: 10034 | F35: 海关总署 | G35: http://www.customs.gov.cn/ | I35: https://www.google.com/s2/favicons?domain=http://www.customs.gov.cn/ | J35: 政府 | K35: 国务院 | L35: 直属机构 | N35: 999 | O35: 999
A36: #REF! | B36: 101 | C36: #REF! | D36: #VALUE! | E36: 10035 | F36: 国家税务总局 | G36: http://www.chinatax.gov.cn/ | I36: https://www.google.com/s2/favicons?domain=http://www.chinatax.gov.cn/ | J36: 政府 | K36: 国务院 | L36: 直属机构 | N36: 999
A37: #REF! | B37: 101 | C37: #REF! | D37: #VALUE! | E37: 10036 | F37: 国家市场监督管理总局 | G37: http://www.samr.gov.cn/ | I37: http://www.samr.gov.cn/favicon.ico | J37: 政府 | K37: 国务院 | L37: 直属机构 | N37: 999 | Q37: 16
A38: #REF! | B38: 101 | C38: #REF! | D38: #VALUE! | E38: 10037 | F38: (国家认证认可监督管理委员会) | G38: http://www.cnca.gov.cn/ | I38: http://www.cnca.gov.cn/favicon.ico | J38: 政府 | K38: 国务院 | L38: 直属机构 | N38: 999 | Q38: 16
A39: #REF! | B39: 101 | C39: #REF! | D39: #VALUE! | E39: 10038 | F39: (国家标准化管理委员会) | G39: http://www.sac.gov.cn/ | I39: http://www.sac.gov.cn/favicon.ico | J39: 政府 | K39: 国务院 | L39: 直属机构 | N39: 999 | Q39: 16
A40: #REF! | B40: 101 | C40: #REF! | D40: #VALUE! | E40: 10039 | F40: 国家广播电视总局 | G40: http://www.nrta.gov.cn/ | I40: http://www.nrta.gov.cn/favicon.ico | J40: 政府 | K40: 国务院 | L40: 直属机构 | N40: 999 | Q40: 32
...

Sheet 首次要关键词
A1: 首要关键词 | B1: 排序 | C1: 次要关键词数量 | D1: 1 | E1: 2 | F1: 3 | G1: 4 | H1: 5 | I1: 6 | J1: 7 | K1: 列1 | L1: 列2 | M1: 列3 | N1: 列4 | O1: 列5 | P1: 列6 | Q1: 列7 | R1: 列8 | S1: 列9 | T1: 列10 | U1: 列11 | V1: 列12 | W1: 列13 | X1: 列14 | Y1: 列15 | Z1: 列16 | AA1: 列17 | AB1: 列18 | AC1: 列19 | AD1: 列20 | AE1: 列21 | AF1: 列22 | AG1: 列23 | AH1: 列24
A2: 政府 | B2: 101 | C2: =COUNTIF(表_首次要关键词[[#This Row],[1]:[列24]],"<>") -> 1 | D2: 国务院
A3: 政协 | B3: =B2+1 -> 102 | C3: =COUNTIF(表_首次要关键词[[#This Row],[1]:[列24]],"<>") -> 31 | D3: 北京市 | E3: 天津市 | F3: 上海市 | G3: 重庆市 | H3: 广西壮族自治区 | I3: 内蒙古自治区 | J3: 宁夏回族自治区 | K3: 西藏自治区 | L3: 新疆维吾尔自治区 | M3: 安徽省 | N3: 福建省 | O3: 甘肃省 | P3: 广东省 | Q3: 贵州省 | R3: 海南省 | S3: 河北省 | T3: 河南省 | U3: 黑龙江省 | V3: 湖北省 | W3: 湖南省 | X3: 吉林省 | Y3: 江苏省 | Z3: 江西省 | AA3: 辽宁省 | AB3: 青海省 | AC3: 山东省 | AD3: 山西省 | AE3: 陕西省 | AF3: 四川省 | AG3: 云南省 | AH3: 浙江省
A4: 媒体 | B4: =B3+10 -> 112 | C4: =COUNTIF(表_首次要关键词[[#This Row],[1]:[列24]],"<>") -> 1 | D4: 中央媒体
A5: 搜索引擎 | B5: 201 | C5: =COUNTIF(表_首次要关键词[[#This Row],[1]:[列24]],"<>") -> 5 | D5: 图片 | E5: 文档 | F5: 百度云盘 | G5: 图书 | H5: 音乐
A6: 网址导航 | B6: =B5+1 -> 202 | C6: =COUNTIF(表_首次要关键词[[#This Row],[1]:[列24]],"<>") -> 0
A7: 门户网站 | B7: =B6+1 -> 203 | C7: =COUNTIF(表_首次要关键词[[#This Row],[1]:[列24]],"<>") -> 0
A8: 新闻 | B8: =B7+1 -> 204 | C8: =COUNTIF(表_首次要关键词[[#This Row],[1]:[列24]],"<>") -> 0
A9: 直播 | B9: 251 | C9: =COUNTIF(表_首次要关键词[[#This Row],[1]:[列24]],"<>") -> 1 | D9: 网络电视
A10: 视频 | B10: =B9+1 -> 252 | C10: =COUNTIF(表_首次要关键词[[#This Row],[1]:[列24]],"<>") -> 0
A11: 音乐 | B11: =B10+1 -> 253 | C11: =COUNTIF(表_首次要关键词[[#This Row],[1]:[列24]],"<>") -> 0
A12: 银行机构 | B12: 301 | C12: =COUNTIF(表_首次要关键词[[#This Row],[1]:[列24]],"<>") -> 5 | D12: 央行 | E12: 政策 | F12: 邮储 | G12: 国有 | H12: 其他
A13: 保险机构 | B13: =B12+1 -> 302 | C13: =COUNTIF(表_首次要关键词[[#This Row],[1]:[列24]],"<>") -> 0
A14: 证券机构 | B14: =B13+1 -> 303 | C14: =COUNTIF(表_首次要关键词[[#This Row],[1]:[列24]],"<>") -> 0
A15: 数字图书馆 | B15: 601 | C15: =COUNTIF(表_首次要关键词[[#This Row],[1]:[列24]],"<>") -> 17 | D15: 北碚图书馆 | E15: 湖北省图书馆 | F15: 湖州市图书馆 | G15: 阆中市图书馆 | H15: 南京图书馆 | I15: 内江师范学院图书馆 | J15: 日本国会图书馆 | K15: 上海图书馆 | L15: 首都图书馆 | M15: 台湾大学台湾历史数位图书馆 | N15: 唐河图书馆 | O15: 英国剑桥大学图书馆 | P15: 云南省图书馆 | Q15: 枣庄市图书馆 | R15: 新加坡国家图书馆 | S15: 山东大学图书馆 | T15: 旧报纸
A16: 数字博物馆 | B16: =B15+1 -> 602 | C16: =COUNTIF(表_首次要关键词[[#This Row],[1]:[列24]],"<>") -> 1 | D16: 天一阁博物馆
A17: 字典 | B17: =B16+1 -> 603 | C17: =COUNTIF(表_首次要关键词[[#This Row],[1]:[列24]],"<>") -> 0
A18: 词典 | B18: =B17+1 -> 604 | C18: =COUNTIF(表_首次要关键词[[#This Row],[1]:[列24]],"<>") -> 0
A19: 古籍 | B19: =B18+1 -> 605 | C19: =COUNTIF(表_首次要关键词[[#This Row],[1]:[列24]],"<>") -> 3 | D19: 搜韵网 | E19: 山东大学图书馆 | F19: 整理文章
A20: Google | B20: 801 | C20: =COUNTIF(表_首次要关键词[[#This Row],[1]:[列24]],"<>") -> 0
A21: 百度 | B21: =B20+1 -> 802 | C21: =COUNTIF(表_首次要关键词[[#This Row],[1]:[列24]],"<>") -> 0
A22: 网易 | B22: =B21+1 -> 803 | C22: =COUNTIF(表_首次要关键词[[#This Row],[1]:[列24]],"<>") -> 0
A23: 网购平台 | B23: 900 | C23: =COUNTIF(表_首次要关键词[[#This Row],[1]:[列24]],"<>") -> 0
A24: 邮箱 | B24: =B23+1 -> 901 | C24: =COUNTIF(表_首次要关键词[[#This Row],[1]:[列24]],"<>") -> 0
A25: 图片 | B25: =B24+1 -> 902 | C25: =COUNTIF(表_首次要关键词[[#This Row],[1]:[列24]],"<>") -> 4 | D25: 壁纸 | E25: 素材 | F25: 图标 | G25: API
A26: 云服务 | B26: =B25+1 -> 903 | C26: =COUNTIF(表_首次要关键词[[#This Row],[1]:[列24]],"<>") -> 0
A27: 在线教育 | B27: =B26+1 -> 904 | C27: =COUNTIF(表_首次要关键词[[#This Row],[1]:[列24]],"<>") -> 0
A28: 社区 | B28: =B27+1 -> 905 | C28: =COUNTIF(表_首次要关键词[[#This Row],[1]:[列24]],"<>") -> 0
A29: 评测 | B29: =B28+1 -> 906 | C29: =COUNTIF(表_首次要关键词[[#This Row],[1]:[列24]],"<>") -> 0
A30: 人力资源 | B30: =B29+1 -> 907 | C30: =COUNTIF(表_首次要关键词[[#This Row],[1]:[列24]],"<>") -> 0
A31: 游戏 | B31: =B30+1 -> 908 | C31: =COUNTIF(表_首次要关键词[[#This Row],[1]:[列24]],"<>") -> 3 | D31: 未区分 | E31: 小游戏 | F31: 单机游戏
A32: 初录未归挡 | B32: 991 | C32: =COUNTIF(表_首次要关键词[[#This Row],[1]:[列24]],"<>") -> 4 | D32: 未区分 | E32: 古籍 | F32: 个人站点 | G32: freepik公司
A33: 初录未归挡1 | B33: =B32+1 -> 992 | C33: =COUNTIF(表_首次要关键词[[#This Row],[1]:[列24]],"<>") -> 1 | D33: 民主党派

Sheet 重点关键词
A1: =VLOOKUP("政府",表_首次要关键词[[#All],[首要关键词]:[排序]],2,0)&"_政府" -> 101_政府 | B1: 国务院
A2: =A1 -> 101_政府 | B2: =COUNTIFS(B3:B50,"<>") -> 7 | C2: =COUNTIFS(C3:C50,"<>") -> 0 | D2: =COUNTIFS(D3:D50,"<>") -> 0 | E2: =COUNTIFS(E3:E50,"<>") -> 0 | F2: =COUNTIFS(F3:F50,"<>") -> 0 | G2: =COUNTIFS(G3:G50,"<>") -> 0 | H2: =COUNTIFS(H3:H50,"<>") -> 0 | I2: =COUNTIFS(I3:I50,"<>") -> 0 | ... AK2: =COUNTIFS(AK3:AK50,"<>") -> 0
A3: =A2 -> 101_政府 | B3: 组成部门
A4: =A3 -> 101_政府 | B4: 直属特设机构
A5: =A4 -> 101_政府 | B5: 直属机构
A6: =A5 -> 101_政府 | B6: 办事机构
A7: =A6 -> 101_政府 | B7: 直属事业单位
A8: =A7 -> 101_政府 | B8: 国家局
A9: =A8 -> 101_政府 | B9: 派出机构
A10: =A9 -> 101_政府
A11: =A10 -> 101_政府
A12: =A11 -> 101_政府
A13: =A12 -> 101_政府
A14: =A13 -> 101_政府
A15: =A14 -> 101_政府
A16: =A15 -> 101_政府
A17: =A16 -> 101_政府
A18: =A17 -> 101_政府
A19: =A18 -> 101_政府
A20: =A19 -> 101_政府
A21: =A20 -> 101_政府
... A50: =A49 -> 101_政府
A51: =VLOOKUP("政协",表_首次要关键词[[#All],[首要关键词]:[排序]],2,0)&"_政协" -> 102_政协 | B51: 北京市 | C51: 天津市 | D51: 上海市 | E51: 重庆市 | F51: 广西壮族自治区 | G51: 内蒙古自治区 | H51: 宁夏回族自治区 | I51: 西藏自治区 | J51: 新疆维吾尔自治区 | K51: 安徽省 | L51: 福建省 | M51: 甘肃省 | N51: 广东省 | O51: 贵州省 | P51: 海南省 | Q51: 河北省 | R51: 河南省 | S51: 黑龙江省 | T51: 湖北省 | U51: 湖南省 | V51: 吉林省 | W51: 江苏省 | X51: 江西省 | Y51: 辽宁省 | Z51: 青海省 | AA51: 山东省 | AB51: 山西省 | AC51: 陕西省 | AD51: 四川省 | AE51: 云南省 | AF51: 浙江省
A52: =A51 -> 102_政协 | B52: =COUNTIFS(B53:B99,"<>") -> 0 | C52: =COUNTIFS(C53:C99,"<>") -> 0 | D52: =COUNTIFS(D53:D99,"<>") -> 0 | E52: =COUNTIFS(E53:E99,"<>") -> 0 | F52: =COUNTIFS(F53:F99,"<>") -> 0 | G52: =COUNTIFS(G53:G99,"<>") -> 0 | H52: =COUNTIFS(H53:H99,"<>") -> 0 | I52: =COUNTIFS(I53:I99,"<>") -> 0 | ... AK52: =COUNTIFS(AK53:AK99,"<>") -> 0
A53: =A52 -> 102_政协 | N53: 广州市 | S53: 哈尔滨市 | T53: 武汉市
A54: =A53 -> 102_政协 | N54: 深圳市
A55: =A54 -> 102_政协 | N55: 珠海市
A56: =A55 -> 102_政协 | N56: 汕头市
A57: =A56 -> 102_政协 | N57: 佛山市
A58: =A57 -> 102_政协 | N58: 韶关市
A59: =A58 -> 102_政协 | N59: 河源市
A60: =A59 -> 102_政协 | N60: 梅州市
A61: =A60 -> 102_政协 | N61: 惠州市
A62: =A61 -> 102_政协 | N62: 汕尾市
A63: =A62 -> 102_政协 | N63: 东莞市
A64: =A63 -> 102_政协 | N64: 中山市
A65: =A64 -> 102_政协 | N65: 江门市
... A72: =A71 -> 102_政协 | N72: 云浮市
A73: =A72 -> 102_政协
A74: =A73 -> 102_政协
...
